<mujoco model="fleetos_lab">
    <compiler angle="degree" inertiafromgeom="true"/>
    <default>
        <joint armature="1" damping="1" limited="true"/>
        <geom conaffinity="1" condim="1" contype="1" margin="0.001" material="geom" rgba="0.8 0.6 .4 1"/>
        <motor ctrllimited="true" ctrlrange="-.4 .4"/>
    </default>
    <option integrator="RK4" iterations="50" solver="PGS" timestep="0.003">
    </option>
    <size nkey="5" nuser_geom="1"/>

    <visual>
        <map fogend="14" fogstart="10"/>
        <quality shadowsize="4096"/>
        <global offwidth="1280" offheight="720"/>
    </visual>

    <asset>
        <texture builtin="gradient" height="512" rgb1=".15 .2 .25" rgb2=".02 .02 .04" type="skybox" width="512"/>

        <!-- Floor: industrial tile -->
        <texture builtin="checker" height="512" name="tex_floor" rgb1="0.15 0.15 0.18" rgb2="0.2 0.2 0.23" type="2d" width="512"/>
        <material name="mat_floor" reflectance="0.3" shininess="0.5" specular="0.4" texrepeat="10 10" texture="tex_floor"/>

        <!-- Walls -->
        <texture builtin="flat" height="64" name="tex_wall" rgb1="0.25 0.27 0.3" rgb2="0.22 0.24 0.27" type="2d" width="64"/>
        <material name="mat_wall" texture="tex_wall" texrepeat="4 2" rgba="0.35 0.37 0.4 1"/>

        <!-- Robot body -->
        <texture builtin="flat" height="128" mark="cross" markrgb="0.4 0.6 0.8" name="texgeom" random="0.01" rgb1="0.3 0.35 0.4" rgb2="0.3 0.35 0.4" type="cube" width="128"/>
        <material name="geom" texture="texgeom" texuniform="true"/>

        <!-- Props -->
        <material name="mat_table" rgba="0.4 0.35 0.3 1" specular="0.2"/>
        <material name="mat_box" rgba="0.7 0.3 0.2 1"/>
        <material name="mat_cylinder" rgba="0.2 0.5 0.7 1"/>
        <material name="mat_marker" rgba="0.1 0.8 0.3 0.5"/>
    </asset>

    <worldbody>
        <!-- Lighting: overhead panels like a lab -->
        <light cutoff="100" diffuse="0.9 0.9 1.0" dir="0 0 -1" directional="true" pos="0 0 4" specular="0.3 0.3 0.3"/>
        <light diffuse="0.4 0.4 0.5" dir="0 -1 -0.5" pos="0 5 3" specular="0.1 0.1 0.1"/>
        <light diffuse="0.3 0.3 0.4" dir="0 1 -0.5" pos="0 -5 3" specular="0.1 0.1 0.1"/>

        <!-- ===== Room Structure ===== -->
        <!-- Floor (10x10m) -->
        <geom name="floor" type="plane" size="5 5 0.1" pos="0 0 0" material="mat_floor" condim="3" friction="1 .1 .1"/>

        <!-- Walls (3m tall) -->
        <geom name="wall_north" type="box" size="5 0.05 1.5" pos="0 5 1.5" material="mat_wall" contype="1" conaffinity="1"/>
        <geom name="wall_south" type="box" size="5 0.05 1.5" pos="0 -5 1.5" material="mat_wall" contype="1" conaffinity="1"/>
        <geom name="wall_east" type="box" size="0.05 5 1.5" pos="5 0 1.5" material="mat_wall" contype="1" conaffinity="1"/>
        <geom name="wall_west" type="box" size="0.05 5 1.5" pos="-5 0 1.5" material="mat_wall" contype="1" conaffinity="1"/>

        <!-- ===== Lab Props ===== -->
        <!-- Workbench -->
        <body name="table" pos="3 3 0">
            <geom name="tabletop" type="box" size="0.6 0.4 0.02" pos="0 0 0.75" material="mat_table" mass="20"/>
            <geom name="table_leg1" type="cylinder" size="0.03 0.37" pos="-0.5 -0.3 0.37" material="mat_table"/>
            <geom name="table_leg2" type="cylinder" size="0.03 0.37" pos="0.5 -0.3 0.37" material="mat_table"/>
            <geom name="table_leg3" type="cylinder" size="0.03 0.37" pos="-0.5 0.3 0.37" material="mat_table"/>
            <geom name="table_leg4" type="cylinder" size="0.03 0.37" pos="0.5 0.3 0.37" material="mat_table"/>
            <!-- Box on table -->
            <geom name="red_box" type="box" size="0.08 0.08 0.08" pos="0.2 0 0.85" material="mat_box" mass="0.5"/>
            <geom name="blue_cylinder" type="cylinder" size="0.05 0.1" pos="-0.2 0.1 0.87" material="mat_cylinder" mass="0.3"/>
        </body>

        <!-- Shelf unit against wall -->
        <body name="shelf" pos="-4.5 0 0">
            <geom name="shelf_back" type="box" size="0.02 1.0 1.0" pos="0 0 1.0" material="mat_table"/>
            <geom name="shelf_bot" type="box" size="0.3 1.0 0.015" pos="0.15 0 0.4" material="mat_table"/>
            <geom name="shelf_mid" type="box" size="0.3 1.0 0.015" pos="0.15 0 0.9" material="mat_table"/>
            <geom name="shelf_top" type="box" size="0.3 1.0 0.015" pos="0.15 0 1.4" material="mat_table"/>
        </body>

        <!-- Floor markers (navigation waypoints) -->
        <geom name="marker_a" type="cylinder" size="0.3 0.001" pos="0 0 0.001" material="mat_marker" contype="0" conaffinity="0"/>
        <geom name="marker_b" type="cylinder" size="0.3 0.001" pos="2 -2 0.001" material="mat_marker" contype="0" conaffinity="0"/>

        <!-- ===== Cameras ===== -->
        <!-- Main overhead angled view (good for seeing the whole room) -->
        <camera name="room_overview" pos="0 -8 6" xyaxes="1 0 0 0 0.6 1" fovy="60"/>
        <!-- Front view -->
        <camera name="front_view" pos="0 -6 2" xyaxes="1 0 0 0 0.3 1" fovy="50"/>
        <!-- Corner surveillance style -->
        <camera name="corner_cam" pos="4.5 -4.5 2.8" xyaxes="1 1 0 0 0 1" fovy="70"/>
        <!-- Top down -->
        <camera name="top_down" pos="0 0 8" xyaxes="1 0 0 0 1 0" fovy="60"/>

        <!-- ===== Humanoid Robot (initial) ===== -->
        <body name="torso" pos="0 0 1.4">
            <camera name="track" mode="trackcom" pos="0 -4 0" xyaxes="1 0 0 0 0 1"/>
            <joint armature="0" damping="0" limited="false" name="root" pos="0 0 0" stiffness="0" type="free"/>
            <geom fromto="0 -.07 0 0 .07 0" name="torso1" size="0.07" type="capsule"/>
            <geom name="head" pos="0 0 .19" size=".09" type="sphere" user="258"/>
            <geom fromto="-.01 -.06 -.12 -.01 .06 -.12" name="uwaist" size="0.06" type="capsule"/>
            <body name="lwaist" pos="-.01 0 -0.260" quat="1.000 0 -0.002 0">
                <geom fromto="0 -.06 0 0 .06 0" name="lwaist" size="0.06" type="capsule"/>
                <joint armature="0.02" axis="0 0 1" damping="5" name="abdomen_z" pos="0 0 0.065" range="-45 45" stiffness="20" type="hinge"/>
                <joint armature="0.02" axis="0 1 0" damping="5" name="abdomen_y" pos="0 0 0.065" range="-75 30" stiffness="10" type="hinge"/>
                <body name="pelvis" pos="0 0 -0.165" quat="1.000 0 -0.002 0">
                    <joint armature="0.02" axis="1 0 0" damping="5" name="abdomen_x" pos="0 0 0.1" range="-35 35" stiffness="10" type="hinge"/>
                    <geom fromto="-.02 -.07 0 -.02 .07 0" name="butt" size="0.09" type="capsule"/>
                    <body name="right_thigh" pos="0 -0.1 -0.04">
                        <joint armature="0.01" axis="1 0 0" damping="5" name="right_hip_x" pos="0 0 0" range="-25 5" stiffness="10" type="hinge"/>
                        <joint armature="0.01" axis="0 0 1" damping="5" name="right_hip_z" pos="0 0 0" range="-60 35" stiffness="10" type="hinge"/>
                        <joint armature="0.0080" axis="0 1 0" damping="5" name="right_hip_y" pos="0 0 0" range="-110 20" stiffness="20" type="hinge"/>
                        <geom fromto="0 0 0 0 0.01 -.34" name="right_thigh1" size="0.06" type="capsule"/>
                        <body name="right_shin" pos="0 0.01 -0.403">
                            <joint armature="0.0060" axis="0 -1 0" name="right_knee" pos="0 0 .02" range="-160 -2" type="hinge"/>
                            <geom fromto="0 0 0 0 0 -.3" name="right_shin1" size="0.049" type="capsule"/>
                            <body name="right_foot" pos="0 0 -0.45">
                                <geom name="right_foot" pos="0 0 0.1" size="0.075" type="sphere" user="0"/>
                            </body>
                        </body>
                    </body>
                    <body name="left_thigh" pos="0 0.1 -0.04">
                        <joint armature="0.01" axis="-1 0 0" damping="5" name="left_hip_x" pos="0 0 0" range="-25 5" stiffness="10" type="hinge"/>
                        <joint armature="0.01" axis="0 0 -1" damping="5" name="left_hip_z" pos="0 0 0" range="-60 35" stiffness="10" type="hinge"/>
                        <joint armature="0.01" axis="0 1 0" damping="5" name="left_hip_y" pos="0 0 0" range="-110 20" stiffness="20" type="hinge"/>
                        <geom fromto="0 0 0 0 -0.01 -.34" name="left_thigh1" size="0.06" type="capsule"/>
                        <body name="left_shin" pos="0 -0.01 -0.403">
                            <joint armature="0.0060" axis="0 -1 0" name="left_knee" pos="0 0 .02" range="-160 -2" stiffness="1" type="hinge"/>
                            <geom fromto="0 0 0 0 0 -.3" name="left_shin1" size="0.049" type="capsule"/>
                            <body name="left_foot" pos="0 0 -0.45">
                                <geom name="left_foot" type="sphere" size="0.075" pos="0 0 0.1" user="0"/>
                            </body>
                        </body>
                    </body>
                </body>
            </body>
            <body name="right_upper_arm" pos="0 -0.17 0.06">
                <joint armature="0.0068" axis="2 1 1" name="right_shoulder1" pos="0 0 0" range="-85 60" stiffness="1" type="hinge"/>
                <joint armature="0.0051" axis="0 -1 1" name="right_shoulder2" pos="0 0 0" range="-85 60" stiffness="1" type="hinge"/>
                <geom fromto="0 0 0 .16 -.16 -.16" name="right_uarm1" size="0.04 0.16" type="capsule"/>
                <body name="right_lower_arm" pos=".18 -.18 -.18">
                    <joint armature="0.0028" axis="0 -1 1" name="right_elbow" pos="0 0 0" range="-90 50" stiffness="0" type="hinge"/>
                    <geom fromto="0.01 0.01 0.01 .17 .17 .17" name="right_larm" size="0.031" type="capsule"/>
                    <geom name="right_hand" pos=".18 .18 .18" size="0.04" type="sphere"/>
                </body>
            </body>
            <body name="left_upper_arm" pos="0 0.17 0.06">
                <joint armature="0.0068" axis="2 -1 1" name="left_shoulder1" pos="0 0 0" range="-60 85" stiffness="1" type="hinge"/>
                <joint armature="0.0051" axis="0 1 1" name="left_shoulder2" pos="0 0 0" range="-60 85" stiffness="1" type="hinge"/>
                <geom fromto="0 0 0 .16 .16 -.16" name="left_uarm1" size="0.04 0.16" type="capsule"/>
                <body name="left_lower_arm" pos=".18 .18 -.18">
                    <joint armature="0.0028" axis="0 -1 -1" name="left_elbow" pos="0 0 0" range="-90 50" stiffness="0" type="hinge"/>
                    <geom fromto="0.01 -0.01 0.01 .17 -.17 .17" name="left_larm" size="0.031" type="capsule"/>
                    <geom name="left_hand" pos=".18 -.18 .18" size="0.04" type="sphere"/>
                </body>
            </body>
        </body>
    </worldbody>

    <tendon>
        <fixed name="left_hipknee">
            <joint coef="-1" joint="left_hip_y"/>
            <joint coef="1" joint="left_knee"/>
        </fixed>
        <fixed name="right_hipknee">
            <joint coef="-1" joint="right_hip_y"/>
            <joint coef="1" joint="right_knee"/>
        </fixed>
    </tendon>

    <actuator>
        <motor gear="100" joint="abdomen_y" name="abdomen_y"/>
        <motor gear="100" joint="abdomen_z" name="abdomen_z"/>
        <motor gear="100" joint="abdomen_x" name="abdomen_x"/>
        <motor gear="100" joint="right_hip_x" name="right_hip_x"/>
        <motor gear="100" joint="right_hip_z" name="right_hip_z"/>
        <motor gear="300" joint="right_hip_y" name="right_hip_y"/>
        <motor gear="200" joint="right_knee" name="right_knee"/>
        <motor gear="100" joint="left_hip_x" name="left_hip_x"/>
        <motor gear="100" joint="left_hip_z" name="left_hip_z"/>
        <motor gear="300" joint="left_hip_y" name="left_hip_y"/>
        <motor gear="200" joint="left_knee" name="left_knee"/>
        <motor gear="25" joint="right_shoulder1" name="right_shoulder1"/>
        <motor gear="25" joint="right_shoulder2" name="right_shoulder2"/>
        <motor gear="25" joint="right_elbow" name="right_elbow"/>
        <motor gear="25" joint="left_shoulder1" name="left_shoulder1"/>
        <motor gear="25" joint="left_shoulder2" name="left_shoulder2"/>
        <motor gear="25" joint="left_elbow" name="left_elbow"/>
    </actuator>
</mujoco>
